##

## 1. try catch(异常类名 变量)

```java
public class Test {
    public static void main(String[] args) {
        method2();
    }

    // 编译时异常
    // ...


    // 运行时异常
    public static void method2() {
        int[] arr = {1, 3, 5};

        try {
            // new ArrayIndexOutOfBoundsException();
            System.out.println(arr[3]);
        } catch (ArrayIndexOutOfBoundsException error) {
            // 提示错误信息, 输出到控制台
            error.printStackTrace();

            // 异常的原因
            System.out.println(error.getMessage());

            // 抛出异常的简短描述
            System.out.println(error.toString());
        }

        System.out.println("继续执行代码");
    }
}
```

## 2. throws 异常类名

```java
// throws 异常类名     抛出异常
public static void method() throws ArrayIndexOutOfBoundsException {
    // ...
}
```

## 3. 自定义异常

```java
// 自定义异常类
public class CustomException extends Exception {
    public CustomException() {

    }

    public CustomException(String message) {
        super(message);
    }
}
```

```java
public class Test {
    public static void main(String[] args) {
        try {
            // throw new 自定义异常类(message)
            throw new CustomException("自定义异常信息");
        } catch(CustomException error) {
            error.printStackTrace();
        }

        System.out.println("继续执行");
    }
}
```
